Traceback (most recent call last):
  File "/home/spr/Documentos/Docencia/teabook/teabook/lib64/python3.9/site-packages/jupyter_cache/executors/utils.py", line 51, in single_nb_execution
    executenb(
  File "/home/spr/Documentos/Docencia/teabook/teabook/lib64/python3.9/site-packages/nbclient/client.py", line 1087, in execute
    return NotebookClient(nb=nb, resources=resources, km=km, **kwargs).execute()
  File "/home/spr/Documentos/Docencia/teabook/teabook/lib64/python3.9/site-packages/nbclient/util.py", line 74, in wrapped
    return just_run(coro(*args, **kwargs))
  File "/home/spr/Documentos/Docencia/teabook/teabook/lib64/python3.9/site-packages/nbclient/util.py", line 53, in just_run
    return loop.run_until_complete(coro)
  File "/usr/lib64/python3.9/asyncio/base_events.py", line 642, in run_until_complete
    return future.result()
  File "/home/spr/Documentos/Docencia/teabook/teabook/lib64/python3.9/site-packages/nbclient/client.py", line 540, in async_execute
    await self.async_execute_cell(
  File "/home/spr/Documentos/Docencia/teabook/teabook/lib64/python3.9/site-packages/nbclient/client.py", line 832, in async_execute_cell
    self._check_raise_for_error(cell, exec_reply)
  File "/home/spr/Documentos/Docencia/teabook/teabook/lib64/python3.9/site-packages/nbclient/client.py", line 740, in _check_raise_for_error
    raise CellExecutionError.from_cell_and_msg(cell, exec_reply['content'])
nbclient.exceptions.CellExecutionError: An error occurred while executing the following cell:
------------------
#!/usr/bin/env python
import matplotlib
from pylab import *
import numpy as np
from matplotlib.pyplot import show
import matplotlib.pyplot as plt
from scipy.interpolate import interp1d
from scipy import integrate,interpolate,stats
import matplotlib.mlab as ml
from math import pi  
from matplotlib.pyplot import figure, show, rc, grid, savefig
from astropy.io import ascii
------------------

[0;31m---------------------------------------------------------------------------[0m
[0;31mModuleNotFoundError[0m                       Traceback (most recent call last)
[0;32m<ipython-input-1-1854a5089600>[0m in [0;36m<module>[0;34m[0m
[1;32m      1[0m [0;31m#!/usr/bin/env python[0m[0;34m[0m[0;34m[0m[0;34m[0m[0m
[0;32m----> 2[0;31m [0;32mimport[0m [0mmatplotlib[0m[0;34m[0m[0;34m[0m[0m
[0m[1;32m      3[0m [0;32mfrom[0m [0mpylab[0m [0;32mimport[0m [0;34m*[0m[0;34m[0m[0;34m[0m[0m
[1;32m      4[0m [0;32mimport[0m [0mnumpy[0m [0;32mas[0m [0mnp[0m[0;34m[0m[0;34m[0m[0m
[1;32m      5[0m [0;32mfrom[0m [0mmatplotlib[0m[0;34m.[0m[0mpyplot[0m [0;32mimport[0m [0mshow[0m[0;34m[0m[0;34m[0m[0m

[0;31mModuleNotFoundError[0m: No module named 'matplotlib'
ModuleNotFoundError: No module named 'matplotlib'

